<?xml version="1.0"?>
<robot name="car_robot">

  <material name="body_color">
    <color rgba= "0 0.5 1 1"/>
  </material> 

  <material name="head_color">
    <color rgba= "1 0 0 1"/>
  </material> 

  <material name="wheel_color">
    <color rgba= "0 0 0 1"/>
  </material> 


  <link name="base_link">
    <visual>
        <origin xyz="0 0 0.15" rpy="0 0 0"/>
        <geometry>
            <box size="0.4 0.4 0.25" />
        </geometry>
        <material name="body_color"/>  
    </visual>
  </link>

  <link name="head_link">
    <visual>
        <origin xyz="0 0 0" rpy="0 0 0"/>
        <geometry>
            <sphere radius= "0.12"/> 
        </geometry>
        <material name="head_color"/>  
    </visual>
  </link>

  <link name="left_wheel_link">
    <visual>
        <origin xyz="0 0 0" rpy="0 0 0"/>
        <geometry>
            <sphere radius= "0.1"/> 
        </geometry>
        <material name="wheel_color"/>  
    </visual>
  </link>

  <link name="right_wheel_link">
    <visual>
        <origin xyz="0 0 0" rpy="0 0 0"/>
        <geometry>
            <sphere radius= "0.1"/> 
        </geometry>
        <material name="wheel_color"/>  
    </visual>
  </link>

  <joint name="base_to_head" type="fixed">
    <parent link="base_link"/>
    <child link="head_link"/>
    <origin xyz="0 0 0.4" rpy="0 0 0"/> 
  </joint>

  <joint name="base_to_left_wheel" type="continuous">
    <parent link="base_link"/>
    <child link="left_wheel_link"/>
    <origin xyz="0.19 0 -0.07" rpy="0 0 0" /> 
    <axis xyz="0 1 0" />
  </joint>


  <joint name="base_to_right_wheel" type="continuous">
    <parent link="base_link"/>
    <child link="right_wheel_link"/>
    <origin xyz="-0.19  0 -0.07" rpy="0 0 0"/> 
    <axis xyz="0 1 0" />
  </joint>




  
</robot>